Workbook

Sheet tabelle totali
A1: Fascia di fatturato/volume d’affari complessivo | B1: Aziende associate
A2: startup | B2: =COUNTIF('TOTALE Soci'!C:C,"startup") -> 11
A3: fino a 2 milioni di euro | B3: =COUNTIF('TOTALE Soci'!C:C,"piccole") -> 22
A4: tra 2 e 10 milioni di euro | B4: =COUNTIF('TOTALE Soci'!C:C,"medie") -> 27
A5: tra 10 e 50 milioni di euro | B5: =COUNTIF('TOTALE Soci'!C:C,"grandi") -> 37
A6: oltre 50 milioni di euro | B6: =COUNTIF('TOTALE Soci'!C:C,"multinazionali") -> 51
B9: Aziende totali
B10: =SUM(Tabella2[Aziende associate]) -> 148
A21: Fascia di fatturato/volume d’affari complessivo | B21: Associati
A22: Startup | B22: =COUNTIF('TOTALE Soci'!C:C,"startup") -> 11
A23: Micro imprese - fino a 2 milioni di euro | B23: =COUNTIF('TOTALE Soci'!C:C,"piccole") -> 22
A24: Piccole imprese - tra 2 e 10 milioni di euro | B24: =COUNTIF('TOTALE Soci'!C:C,"medie") -> 27
A25: Medie imprese - tra 10 e 50 milioni di euro | B25: =COUNTIF('TOTALE Soci'!C:C,"grandi") -> 37
A26: Grandi imprese - oltre 50 milioni di euro | B26: =COUNTIF('TOTALE Soci'!C:C,"multinazionali") -> 51
A27: Banche | B27: =COUNTIF('TOTALE Soci'!C:C,"banche") -> 7
A28: Associazioni industriali | B28: =COUNTIF('TOTALE Soci'!C:C,"associazione") -> 19
B30: Associati totali
B31: =SUM(Tabella24[Associati]) -> 174
A49: Settore | B49: Associati
A50: energia, gas, luce, acqua, ambiente, estrattiva, metallurgia | B50: =COUNTIF('TOTALE Soci'!B:B,Tabella247[[#This Row],[Settore]]) -> 24
A51: agroalimentare | B51: =COUNTIF('TOTALE Soci'!B:B,Tabella247[[#This Row],[Settore]]) -> 10
A52: media, editoria | B52: =COUNTIF('TOTALE Soci'!B:B,Tabella247[[#This Row],[Settore]]) -> 2
A53: edilizia, infrastrutture, materiali da costruzione | B53: =COUNTIF('TOTALE Soci'!B:B,Tabella247[[#This Row],[Settore]]) -> 27
A54: elettronica, ICT, digitale | B54: =COUNTIF('TOTALE Soci'!B:B,Tabella247[[#This Row],[Settore]]) -> 12
A55: macchinari, attrezzature, impianti | B55: =COUNTIF('TOTALE Soci'!B:B,Tabella247[[#This Row],[Settore]]) -> 34
A56: servizi alle imprese | B56: =COUNTIF('TOTALE Soci'!B:B,Tabella247[[#This Row],[Settore]]) -> 15
A57: associazioni industriali | B57: =COUNTIF('TOTALE Soci'!B:B,Tabella247[[#This Row],[Settore]]) -> 19
A58: banche | B58: =COUNTIF('TOTALE Soci'!B:B,Tabella247[[#This Row],[Settore]]) -> 7
A59: carta, legno, arredamento | B59: =COUNTIF('TOTALE Soci'!B:B,Tabella247[[#This Row],[Settore]]) -> 4
A60: gomma, plastica, chimica | B60: =COUNTIF('TOTALE Soci'!B:B,Tabella247[[#This Row],[Settore]]) -> 5
A61: logistica, trasporti | B61: =COUNTIF('TOTALE Soci'!B:B,Tabella247[[#This Row],[Settore]]) -> 10
... A63: farmaceutica, sanità | B63: =COUNTIF('TOTALE Soci'!B:B,Tabella247[[#This Row],[Settore]]) -> 3
B65: tot.
B66: =SUM(Tabella247[Associati]) -> 174

Sheet TOTALE Soci
A1: AZIENDA | B1: SETTORE | C1: FASCIA FATTURATO | D1: FATTURATO | E1: QUOTE 2026 | F1: sito
A2: 3Bmust INTERNATIONAL | B2: macchinari, attrezzature, impianti | C2: piccole | D2: 1500000 | F2: ok
A3: A.R. TECHNOLOGY | B3: energia, gas, luce, acqua, ambiente, estrattiva, metallurgia | C3: grandi | D3: 11500000 | F3: ok
A4: ABYTU | B4: energia, gas, luce, acqua, ambiente, estrattiva, metallurgia | C4: piccole | D4: 400000 | F4: ok
A5: ACEA SPA | B5: energia, gas, luce, acqua, ambiente, estrattiva, metallurgia | C5: multinazionali | D5: 1000000000 | F5: ok
A6: ADRAGNA | B6: agroalimentare | C6: medie | D6: 7500000 | F6: ok
A7: AFLABOX | B7: agroalimentare | C7: startup
A8: AGENZIA DI STAMPA ITALPRESS | B8: media, editoria | C8: medie | D8: 6650000 | F8: ok
A9: AIRCONTAINER | B9: logistica, trasporti | C9: piccole | D9: 4500000 | F9: ok
A10: ALGECO | B10: edilizia, infrastrutture, materiali da costruzione | C10: multinazionali | D10: 74000000 | F10: ok
A11: ALMAVIVA | B11: elettronica, ICT, digitale | C11: multinazionali | D11: 946000000 | F11: ok
A12: ALMAWAVE | B12: elettronica, ICT, digitale | C12: multinazionali | D12: 57000000 | F12: ok
A13: ANDERSEN | B13: servizi alle imprese | C13: grandi | D13: 29500000 | F13: ok
A14: ANIE FEDERAZIONE | B14: Associazioni industriali | C14: associazione | F14: ok
A15: ANITEC-ASSINFORM - Associazione Italiana per l’Information and Communication Technology (ICT) | B15: Associazioni industriali | C15: associazione | F15: ok
A16: ARAB BANKING CORPORATION | B16: banche | C16: banche | D16: 25000000 | F16: ok
A17: ARET video and audio engineering | B17: macchinari, attrezzature, impianti | C17: grandi | D17: 17000000 | F17: ok
A18: ARGIOLAS FORMAGGI | B18: agroalimentare | C18: grandi | D18: 19000000 | F18: ok
A19: ASSOCIATED MEDIAS | B19: media, editoria | C19: piccole | D19: 250000 | F19: ok
A20: ASSOCIAZIONE INDUSTRIALI CREMONA | B20: Associazioni industriali | C20: associazione | F20: ok
A21: ASSOLOMBARDA | B21: Associazioni industriali | C21: associazione | F21: ok
A22: ASSOMAC | B22: Associazioni industriali | C22: associazione | F22: ok
A23: ATP TECHNOLOGIES | B23: servizi alle imprese | C23: startup | D23: 200000 | F23: ok
A24: AVIOGEI | B24: macchinari, attrezzature, impianti | C24: grandi | D24: 14000000 | F24: ok
A25: AYMING ITALIA SRL SB | B25: servizi alle imprese | C25: medie | D25: 4000000 | F25: ok
A26: BALTUR | B26: energia, gas, luce, acqua, ambiente, estrattiva, metallurgia | C26: grandi | D26: 44000000
A27: BANCA MONTE DEI PASCHI DI SIENA | B27: banche | C27: banche | D27: 3800000000 | F27: ok
A28: BANCA POPOLARE DI SONDRIO | B28: banche | C28: banche | D28: 1300000000 | F28: ok
A29: BANCA UBAE | B29: banche | C29: banche | D29: 52000000 | F29: ok
A30: BCC STUDIO | B30: elettronica, ICT, digitale | C30: startup | D30: 250000 | F30: ok
A31: BEA TECHNOLOGIES | B31: macchinari, attrezzature, impianti | C31: grandi | D31: 18000000 | F31: ok
A32: BEDESCHI | B32: macchinari, attrezzature, impianti | C32: multinazionali | D32: 200000000 | F32: ok
A33: BERGS & MORE | B33: servizi alle imprese | C33: medie | D33: 2100000 | F33: ok
A34: BLEND PLANTS | B34: macchinari, attrezzature, impianti | C34: medie | D34: 10000000 | F34: ok
A35: BONELLI EREDE | B35: servizi alle imprese | C35: multinazionali | D35: 150000000 | F35: ok
A36: BTT ITALIA | B36: energia, gas, luce, acqua, ambiente, estrattiva, metallurgia | C36: medie | D36: 4000000 | F36: ok
A37: BUREAU VERITAS ITALIA SPA | B37: servizi alle imprese | C37: multinazionali | D37: 200000000 | F37: ok
A38: CAPRARI | B38: macchinari, attrezzature, impianti | C38: multinazionali | D38: 140000000 | F38: ok
... A43: CONDOTTE 1880 | B43: edilizia, infrastrutture, materiali da costruzione | C43: multinazionali | D43: 250000000 | F43: ok
A44: CONFINDUSTRIA ABRUZZO MEDIO ADRIATICO | B44: Associazioni industriali | C44: associazione | F44: ok
...
